Workbook
Name Slicer_Defect_Category: #N/A
Name Slicer_Status1: #N/A
Name status: 'CAR LOG'!#REF!
Name type: Lists!#REF!

Sheet Komatsu 2021
A1: Cambridge 60778
A2: Month | B2: Defect Notice Count All | C2: Defect Notice Productioon | D2: Defect Notice In Process Machining | E2: Defect Notice Raw Material | F2: Defect Notice NPI/PPAP | G2: Defect Notice PPD Parts | H2: No Defect Claims Early Life Failure | I2: Green Target | J2: Yellow Target | K2: Red Target | L2: Production DPU | M2: Production Average FY DPU | N2: Green Target | O2: Yellow Target | P2: Red Target | Q2: Q1 | R2: Q2 | S2: Q3 | T2: Q4 | U2: Defect Notice Rolling Quarterly Average | V2: No Defect Claims Early Life Failure
A3: 2019 avg monthy defects | C3: 15.16 | L3: 0.69 | M3: 0.69 | N3: 0.25 | O3: 1 | P3: 1.01 | Q3: 44 | R3: 45 | S3: 54 | T3: 39 | U3: 45.5
A4: 2020 avg monthy defects | C4: 7.75 | L4: 0.36 | M4: 0.36 | N4: 0.25 | O4: 1 | P4: 1.01 | Q4: 24 | R4: 16 | S4: 24 | T4: 29 | U4: 23.3
A5: 2021 avg monthy defects | C5: 4.5 | L5: 0.18 | M5: 0.18 | N5: 0.25 | O5: 1 | P5: 1.01 | Q5: 19 | R5: 9 | S5: 10 | T5: 16 | U5: 13.5
A6: Apr | B6: 8 | C6: 7 | D6: 0 | E6: 0 | F6: 0 | G6: 0 | H6: 0 | I6: 0 | J6: 1 | K6: 2 | L6: 0.28 | M6: 0.28 | N6: 0.25 | O6: 1 | P6: 1.01 | Q6: 8 | R6: 0 | S6: 0 | T6: 0 | U6: 2 | V6: 0
A7: May | B7: 7 | C7: 5 | D7: 0 | E7: 0 | F7: 2 | G7: 0 | H7: 0 | I7: 0 | J7: 1 | K7: 2 | L7: 0.2 | M7: 0.26 | N7: 0.25 | O7: 1 | P7: 1.01 | Q7: 15 | R7: 0 | S7: 0 | T7: 0 | U7: 3.8 | V7: 0
A8: Jun | B8: 4 | C8: 2 | D8: 0 | E8: 0 | F8: 0 | G8: 2 | H8: 0 | I8: 0 | J8: 1 | K8: 2 | L8: 0.08 | M8: 0.21 | N8: 0.25 | O8: 1 | P8: 1.01 | Q8: 19 | R8: 7 | S8: 0 | T8: 0 | U8: 6.5 | V8: 0
A9: Jul | B9: 4 | C9: 3 | D9: 0 | E9: 0 | F9: 1 | G9: 0 | H9: 0 | I9: 0 | J9: 1 | K9: 2 | L9: 0.12 | M9: 0.2 | N9: 0.25 | O9: 1 | P9: 1.01 | Q9: 19 | R9: 7 | S9: 0 | T9: 0 | U9: 6.5 | V9: 0
A10: Aug | B10: 3 | C10: 1 | D10: 0 | E10: 1 | F10: 0 | G10: 1 | H10: 0 | I10: 0 | J10: 1 | K10: 2 | L10: 0.04 | M10: 0.18 | N10: 0.25 | O10: 1 | P10: 1.01 | Q10: 19 | R10: 7 | S10: 0 | T10: 0 | U10: 6.5 | V10: 0
A11: Sep | B11: 2 | C11: 2 | D11: 0 | E11: 0 | F11: 0 | G11: 0 | H11: 0 | I11: 0 | J11: 1 | K11: 2 | L11: 0.08 | M11: 0.17 | N11: 0.25 | O11: 1 | P11: 1.01 | Q11: 19 | R11: 9 | S11: 0 | T11: 0 | U11: 7 | V11: 0
A12: Oct | B12: 1 | C12: 1 | D12: 0 | E12: 0 | F12: 0 | G12: 0 | H12: 0 | I12: 0 | J12: 1 | K12: 2 | L12: 0.04 | M12: 0.16 | N12: 0.25 | O12: 1 | P12: 1.01 | Q12: 19 | R12: 9 | S12: 1 | T12: 0 | U12: 7.3 | V12: 0
A13: Nov | B13: 3 | C13: 1 | D13: 0 | E13: 1 | F13: 1 | G13: 0 | H13: 0 | I13: 0 | J13: 1 | K13: 2 | L13: 0.04 | M13: 0.15 | N13: 0.25 | O13: 1 | P13: 1.01 | Q13: 19 | R13: 8 | S13: 4 | T13: 0 | U13: 8 | V13: 0
A14: Dec | B14: 6 | C14: 0 | D14: 0 | E14: 0 | F14: 5 | G14: 1 | H14: 0 | I14: 0 | J14: 1 | K14: 2 | L14: 0 | M14: 0.15 | N14: 0.25 | O14: 1 | P14: 1.01 | Q14: 19 | R14: 9 | S14: 10 | T14: 0 | U14: 9.5 | V14: 0
A15: Jan | B15: 1 | C15: 1 | D15: 0 | E15: 0 | F15: 0 | G15: 0 | H15: 0 | I15: 0 | J15: 1 | K15: 2 | L15: 0.04 | M15: 0.14 | N15: 0.25 | O15: 1 | P15: 1.01 | Q15: 19 | R15: 9 | S15: 10 | T15: 1 | U15: 9.8 | V15: 0
A16: Feb | B16: 6 | C16: 4 | D16: 0 | E16: 1 | F16: 1 | G16: 0 | H16: 0 | I16: 0 | J16: 1 | K16: 2 | L16: 0.16 | M16: 0.17 | N16: 0.25 | O16: 1 | P16: 1.01 | Q16: 19 | R16: 9 | S16: 10 | T16: 7 | U16: 11.3 | V16: 0
A17: Mar | B17: 9 | C17: 6 | D17: 0 | E17: 1 | F17: 2 | G17: 0 | H17: 0 | I17: 0 | J17: 1 | K17: 2 | L17: 0.24 | M17: 0.18 | N17: 0.25 | O17: 1 | P17: 1.01 | Q17: 19 | R17: 9 | S17: 10 | T17: 16 | U17: 13.5 | V17: 0
A19: Woodstock 60782
A20: Month | B20: Defect Notice Count All | C20: Defect Notice Productioon | D20: Defect Notice In Process Machining | E20: Defect Notice Raw Material | F20: Defect Notice NPI/PPAP | G20: Defect Notice PPD Parts | H20: No Defect Claims Early Life Failure | I20: Green Target | J20: Yellow Target | K20: Red Target | L20: Production DPU | M20: Production Average FY DPU | N20: Green Target | O20: Yellow Target | P20: Red Target | Q20: Q1 | R20: Q2 | S20: Q3 | T20: Q4 | U20: Defect Notice Rolling Quarterly Average | V20: No Defect Claims Early Life Failure
A21: 2019 avg monthy defects | C21: 2.92 | L21: 0.17 | M21: 0.17 | N21: 0.25 | O21: 1 | P21: 1.01 | Q21: 11 | R21: 8 | S21: 5 | T21: 11 | U21: 8.8
A22: 2020 avg monthy defects | C22: 1.25 | L22: 0.08 | M22: 0.08 | N22: 0.25 | O22: 1 | P22: 1.01 | Q22: 5 | R22: 6 | S22: 3 | T22: 3 | U22: 3.8
A23: 2021 avg monthy defects | C23: 1.166 | L23: 0.08 | M23: 0.08 | N23: 0.25 | O23: 1 | P23: 1.01 | Q23: 1 | R23: 5 | S23: 4 | T23: 4 | U23: 3.5
A24: Apr | B24: 0 | C24: 0 | D24: 0 | E24: 0 | F24: 0 | G24: 0 | H24: 0 | I24: 0 | J24: 1 | K24: 2 | L24: 0 | M24: 0 | N24: 0.25 | O24: 1 | P24: 1.01 | Q24: 0 | R24: 0 | S24: 0 | T24: 0 | U24: 0.5 | V24: 0
A25: May | B25: 1 | C25: 1 | D25: 0 | E25: 0 | F25: 0 | G25: 0 | H25: 0 | I25: 0 | J25: 1 | K25: 2 | L25: 0.04 | M25: 0.02 | N25: 0.25 | O25: 1 | P25: 1.01 | Q25: 1 | R25: 0 | S25: 0 | T25: 0 | U25: 0.3 | V25: 0
A26: Jun | B26: 0 | C26: 0 | D26: 0 | E26: 0 | F26: 0 | G26: 0 | H26: 0 | I26: 0 | J26: 1 | K26: 2 | L26: 0 | M26: 0.01 | N26: 0.25 | O26: 1 | P26: 1.01 | Q26: 1 | R26: 0 | S26: 0 | T26: 0 | U26: 0.3 | V26: 0
A27: Jul | B27: 1 | C27: 1 | D27: 0 | E27: 0 | F27: 0 | G27: 0 | H27: 0 | I27: 0 | J27: 1 | K27: 2 | L27: 0.04 | M27: 0.02 | N27: 0.25 | O27: 1 | P27: 1.01 | Q27: 1 | R27: 3 | S27: 0 | T27: 0 | U27: 1 | V27: 0
A28: Aug | B28: 2 | C28: 2 | D28: 0 | E28: 0 | F28: 0 | G28: 0 | H28: 0 | I28: 0 | J28: 1 | K28: 2 | L28: 0.08 | M28: 0.04 | N28: 0.25 | O28: 1 | P28: 1.01 | Q28: 1 | R28: 3 | S28: 0 | T28: 0 | U28: 1 | V28: 0
A29: Sep | B29: 2 | C29: 2 | D29: 0 | E29: 0 | F29: 0 | G29: 0 | H29: 0 | I29: 0 | J29: 1 | K29: 2 | L29: 0.08 | M29: 0.05 | N29: 0.25 | O29: 1 | P29: 1.01 | Q29: 1 | R29: 5 | S29: 0 | T29: 0 | U29: 1.5 | V29: 0
A30: Oct | B30: 0 | C30: 0 | D30: 0 | E30: 0 | F30: 0 | G30: 0 | H30: 0 | I30: 0 | J30: 1 | K30: 2 | L30: 0 | M30: 0.04 | N30: 0.25 | O30: 1 | P30: 1.01 | Q30: 1 | R30: 5 | S30: 0 | T30: 0 | U30: 1.5 | V30: 0
A31: Nov | B31: 3 | C31: 3 | D31: 0 | E31: 0 | F31: 0 | G31: 0 | H31: 0 | I31: 0 | J31: 1 | K31: 2 | L31: 0.12 | M31: 0.06 | N31: 0.25 | O31: 1 | P31: 1.01 | Q31: 1 | R31: 5 | S31: 3 | T31: 0 | U31: 2.3 | V31: 0
A32: Dec | B32: 1 | C32: 1 | D32: 0 | E32: 0 | F32: 0 | G32: 0 | H32: 0 | I32: 0 | J32: 1 | K32: 2 | L32: 0.04 | M32: 0.07 | N32: 0.25 | O32: 1 | P32: 1.01 | Q32: 1 | R32: 5 | S32: 4 | T32: 0 | U32: 2.5 | V32: 0
A33: Jan | B33: 2 | C33: 2 | D33: 0 | E33: 0 | F33: 0 | G33: 0 | H33: 0 | I33: 0 | J33: 1 | K33: 2 | L33: 0.08 | M33: 0.07 | N33: 0.25 | O33: 1 | P33: 1.01 | Q33: 1 | R33: 5 | S33: 4 | T33: 2 | U33: 3 | V33: 0
A34: Feb | B34: 1 | C34: 1 | D34: 0 | E34: 0 | F34: 0 | G34: 0 | H34: 0 | I34: 0 | J34: 1 | K34: 2 | L34: 0.04 | M34: 0.08 | N34: 0.25 | O34: 1 | P34: 1.01 | Q34: 1 | R34: 5 | S34: 4 | T34: 3 | U34: 3.3 | V34: 0
A35: Mar | B35: 1 | C35: 1 | D35: 0 | E35: 0 | F35: 0 | G35: 0 | H35: 0 | I35: 0 | J35: 1 | K35: 2 | L35: 0.04 | M35: 0.08 | N35: 0.25 | O35: 1 | P35: 1.01 | Q35: 1 | R35: 5 | S35: 4 | T35: 4 | U35: 3.5 | V35: 0
B77: Studs off location
I79: video

Sheet Komatsu 2020
A1: Cambridge 60778
A2: Month | B2: Defect Notice Count All | C2: Defect Notice Productioon | D2: Defect Notice In Process Machining | E2: Defect Notice Raw Material | F2: Defect Notice NPI/PPAP | G2: Defect Notice PPD Parts | H2: No Defect Claims Early Life Failure | I2: Green Target | J2: Yellow Target | K2: Red Target | L2: Production DPU | M2: Production Average FY DPU | N2: Green Target | O2: Yellow Target | P2: Red Target | Q2: Q1 | R2: Q2 | S2: Q3 | T2: Q4 | U2: Defect Notice Rolling Quarterly Average | V2: No Defect Claims Early Life Failure
A3: 2019 avg monthy defects | C3: 15.16 | L3: 0.69 | M3: 0.69 | N3: 0.25 | O3: 1 | P3: 1.01 | Q3: 44 | R3: 45 | S3: 54 | T3: 39 | U3: 45.5
A4: Apr | B4: 14 | C4: 14 | D4: 0 | E4: 0 | F4: 0 | G4: 0 | H4: 0 | I4: 0 | J4: 1 | K4: 2 | L4: 0.7 | M4: 0.7 | N4: 0.25 | O4: 1 | P4: 1.01 | Q4: 14 | R4: 0 | S4: 0 | T4: 0 | U4: 3.5 | V4: 0
A5: May | B5: 5 | C5: 4 | D5: 0 | E5: 0 | F5: 1 | G5: 0 | H5: 0 | I5: 0 | J5: 1 | K5: 2 | L5: 0.2 | M5: 0.49 | N5: 0.25 | O5: 1 | P5: 1.01 | Q5: 19 | R5: 0 | S5: 0 | T5: 0 | U5: 4.8 | V5: 0
A6: Jun | B6: 7 | C6: 5 | D6: 0 | E6: 0 | F6: 2 | G6: 0 | H6: 0 | I6: 0 | J6: 1 | K6: 2 | L6: 0.25 | M6: 0.41 | N6: 0.25 | O6: 1 | P6: 1.01 | Q6: 26 | R6: 0 | S6: 0 | T6: 0 | U6: 6.5 | V6: 0
A7: Jul | B7: 9 | C7: 6 | D7: 0 | E7: 0 | F7: 2 | G7: 1 | H7: 0 | I7: 0 | J7: 1 | K7: 2 | L7: 0.3 | M7: 0.4 | N7: 0.25 | O7: 1 | P7: 1.01 | Q7: 26 | R7: 9 | S7: 0 | T7: 0 | U7: 8.8 | V7: 0
A8: Aug | B8: 4 | C8: 3 | D8: 0 | E8: 0 | F8: 1 | G8: 0 | H8: 0 | I8: 0 | J8: 1 | K8: 2 | L8: 0.15 | M8: 0.42 | N8: 0.25 | O8: 1 | P8: 1.01 | Q8: 24 | R8: 12 | S8: 0 | T8: 0 | U8: 9 | V8: 0
A9: Sep | B9: 4 | C9: 3 | D9: 0 | E9: 0 | F9: 1 | G9: 0 | H9: 0 | I9: 0 | J9: 1 | K9: 2 | L9: 0.15 | M9: 0.46 | N9: 0.25 | O9: 1 | P9: 1.01 | Q9: 24 | R9: 16 | S9: 0 | T9: 0 | U9: 10 | V9: 0
A10: Oct | B10: 5 | C10: 3 | D10: 0 | E10: 1 | F10: 0 | G10: 1 | H10: 0 | I10: 0 | J10: 1 | K10: 2 | L10: 0.15 | M10: 0.4 | N10: 0.25 | O10: 1 | P10: 1.01 | Q10: 24 | R10: 16 | S10: 5 | T10: 0 | U10: 11.3 | V10: 0
A11: Nov | B11: 8 | C11: 5 | D11: 0 | E11: 1 | F11: 1 | G11: 1 | H11: 0 | I11: 0 | J11: 1 | K11: 2 | L11: 0.25 | M11: 0.38 | N11: 0.25 | O11: 1 | P11: 1.01 | Q11: 24 | R11: 16 | S11: 13 | T11: 0 | U11: 13.3 | V11: 0
A12: Dec | B12: 11 | C12: 5 | D12: 0 | E12: 2 | F12: 4 | G12: 0 | H12: 0 | I12: 0 | J12: 1 | K12: 2 | L12: 0.25 | M12: 0.37 | N12: 0.25 | O12: 1 | P12: 1.01 | Q12: 24 | R12: 16 | S12: 24 | T12: 0 | U12: 16 | V12: 0
A13: Jan | B13: 9 | C13: 8 | D13: 0 | E13: 0 | F13: 1 | G13: 0 | H13: 0 | I13: 0 | J13: 1 | K13: 2 | L13: 0.4 | M13: 0.38 | N13: 0.25 | O13: 1 | P13: 1.01 | Q13: 24 | R13: 16 | S13: 24 | T13: 9 | U13: 18.3 | V13: 0
A14: Feb | B14: 12 | C14: 8 | D14: 0 | E14: 2 | F14: 2 | G14: 0 | H14: 0 | I14: 0 | J14: 1 | K14: 2 | L14: 0.4 | M14: 0.38 | N14: 0.25 | O14: 1 | P14: 1.01 | Q14: 24 | R14: 16 | S14: 24 | T14: 21 | U14: 21.3 | V14: 0
A15: Mar | B15: 8 | C15: 6 | D15: 0 | E15: 0 | F15: 0 | G15: 2 | H15: 0 | I15: 0 | J15: 1 | K15: 2 | L15: 0.3 | M15: 0.36 | N15: 0.25 | O15: 1 | P15: 1.01 | Q15: 24 | R15: 16 | S15: 24 | T15: 29 | U15: 23.3 | V15: 0
A17: Woodstock 60782
A18: Month | B18: Defect Notice Count All | C18: Defect Notice Productioon | D18: Defect Notice In Process Machining | E18: Defect Notice Raw Material | F18: Defect Notice NPI/PPAP | G18: Defect Notice PPD Parts | H18: No Defect Claims Early Life Failure | I18: Green Target | J18: Yellow Target | K18: Red Target | L18: Production DPU | M18: Production Average FY DPU | N18: Green Target | O18: Yellow Target | P18: Red Target | Q18: Q1 | R18: Q2 | S18: Q3 | T18: Q4 | U18: Defect Notice Rolling Quarterly Average | V18: No Defect Claims Early Life Failure
A19: 2019 avg monthy defects | C19: 2.92 | L19: 0.17 | M19: 0.17 | N19: 0.25 | O19: 1 | P19: 1.01 | Q19: 11 | R19: 8 | S19: 5 | T19: 11 | U19: 8.8
A20: Apr | B20: 2 | C20: 2 | D20: 0 | E20: 0 | F20: 0 | G20: 0 | H20: 0 | I20: 0 | J20: 1 | K20: 2 | L20: 0.15 | M20: 0.15 | N20: 0.25 | O20: 1 | P20: 1.01 | Q20: 2 | R20: 0 | S20: 0 | T20: 0 | U20: 0.5 | V20: 0
A21: May | B21: 1 | C21: 1 | D21: 0 | E21: 0 | F21: 0 | G21: 0 | H21: 0 | I21: 0 | J21: 1 | K21: 2 | L21: 0.05 | M21: 0.08 | N21: 0.25 | O21: 1 | P21: 1.01 | Q21: 3 | R21: 0 | S21: 0 | T21: 0 | U21: 0.8 | V21: 0
A22: Jun | B22: 2 | C22: 2 | D22: 0 | E22: 0 | F22: 0 | G22: 0 | H22: 0 | I22: 0 | J22: 1 | K22: 2 | L22: 0.1 | M22: 0.09 | N22: 0.25 | O22: 1 | P22: 1.01 | Q22: 5 | R22: 0 | S22: 0 | T22: 0 | U22: 1.3 | V22: 0
A23: Jul | B23: 1 | C23: 1 | D23: 0 | E23: 0 | F23: 0 | G23: 0 | H23: 0 | I23: 0 | J23: 1 | K23: 2 | L23: 0.05 | M23: 0.08 | N23: 0.25 | O23: 1 | P23: 1.01 | Q23: 5 | R23: 1 | S23: 0 | T23: 0 | U23: 1.5 | V23: 0
A24: Aug | B24: 0 | C24: 0 | D24: 0 | E24: 0 | F24: 0 | G24: 0 | H24: 0 | I24: 0 | J24: 1 | K24: 2 | L24: 0 | M24: 0.08 | N24: 0.25 | O24: 1 | P24: 1.01 | Q24: 5 | R24: 1 | S24: 0 | T24: 0 | U24: 1.5 | V24: 0
A25: Sep | B25: 3 | C25: 3 | D25: 0 | E25: 0 | F25: 0 | G25: 0 | H25: 0 | I25: 0 | J25: 1 | K25: 2 | L25: 0.15 | M25: 0.13 | N25: 0.25 | O25: 1 | P25: 1.01 | Q25: 5 | R25: 4 | S25: 0 | T25: 0 | U25: 2.3 | V25: 0
A26: Oct | B26: 1 | C26: 1 | D26: 0 | E26: 0 | F26: 0 | G26: 0 | H26: 0 | I26: 0 | J26: 1 | K26: 2 | L26: 0.05 | M26: 0.11 | N26: 0.25 | O26: 1 | P26: 1.01 | Q26: 5 | R26: 4 | S26: 1 | T26: 0 | U26: 2.5 | V26: 0
A27: Nov | B27: 0 | C27: 0 | D27: 0 | E27: 0 | F27: 0 | G27: 0 | H27: 0 | I27: 0 | J27: 1 | K27: 2 | L27: 0 | M27: 0.09 | N27: 0.25 | O27: 1 | P27: 1.01 | Q27: 5 | R27: 4 | S27: 1 | T27: 0 | U27: 2.5 | V27: 0
A28: Dec | B28: 2 | C28: 3 | D28: 0 | E28: 0 | F28: 0 | G28: 0 | H28: 0 | I28: 0 | J28: 1 | K28: 2 | L28: 0.1 | M28: 0.1 | N28: 0.25 | O28: 1 | P28: 1.01 | Q28: 5 | R28: 4 | S28: 3 | T28: 0 | U28: 3 | V28: 0
A29: Jan | B29: 1 | C29: 1 | D29: 0 | E29: 0 | F29: 0 | G29: 0 | H29: 0 | I29: 0 | J29: 1 | K29: 2 | L29: 0.5 | M29: 0.09 | N29: 0.25 | O29: 1 | P29: 1.01 | Q29: 5 | R29: 4 | S29: 3 | T29: 1 | U29: 3.3 | V29: 0
A30: Feb | B30: 1 | C30: 1 | D30: 0 | E30: 0 | F30: 0 | G30: 0 | H30: 0 | I30: 0 | J30: 1 | K30: 2 | L30: 0.05 | M30: 0.08 | N30: 0.25 | O30: 1 | P30: 1.01 | Q30: 5 | R30: 4 | S30: 3 | T30: 2 | U30: 3.5 | V30: 0
A31: Mar | B31: 1 | C31: 1 | D31: 0 | E31: 0 | F31: 0 | G31: 0 | H31: 0 | I31: 0 | J31: 1 | K31: 2 | L31: 0.05 | M31: 0.08 | N31: 0.25 | O31: 1 | P31: 1.01 | Q31: 5 | R31: 4 | S31: 3 | T31: 3 | U31: 3.8 | V31: 0

Sheet Komatsu 2022
A1: Cambridge 60778
A2: Month | B2: Defect Notice Count All | C2: Defect Notice Productioon | D2: Defect Notice In Process Machining | E2: Defect Notice Raw Material | F2: Defect Notice NPI/PPAP | G2: Defect Notice PPD Parts | H2: No Defect Claims Early Life Failure | I2: Green Target | J2: Yellow Target | K2: Red Target | L2: Production DPU | M2: Production Average FY DPU | N2: Green Target | O2: Yellow Target | P2: Red Target | Q2: Q1 | R2: Q2 | S2: Q3 | T2: Q4 | U2: Defect Notice Rolling Quarterly Average | V2: No Defect Claims Early Life Failure
A3: 2019 avg monthy defects | C3: 15.16 | L3: 0.69 | M3: 0.69 | N3: 0.25 | O3: 1 | P3: 1.01 | Q3: 44 | R3: 45 | S3: 54 | T3: 39 | U3: 45.5
A4: 2020 avg monthy defects | C4: 7.75 | L4: 0.36 | M4: 0.36 | N4: 0.25 | O4: 1 | P4: 1.01 | Q4: 24 | R4: 16 | S4: 24 | T4: 29 | U4: 23.3
A5: 2021 avg monthy defects | C5: 4.5 | L5: 0.18 | M5: 0.18 | N5: 0.25 | O5: 1 | P5: 1.01 | Q5: 19 | R5: 9 | S5: 10 | T5: 16 | U5: 13.5
A6: Apr | B6: 8 | C6: 5 | D6: 0 | E6: 1 | F6: 2 | G6: 0 | H6: 0 | I6: 0 | J6: 1 | K6: 2 | L6: 0.28 | M6: 0.28 | N6: 0.25 | O6: 1 | P6: 1.01 | Q6: 8 | R6: 0 | S6: 0 | T6: 0 | U6: 2 | V6: 0
A7: May | B7: 2 | C7: 1 | D7: 0 | E7: 1 | F7: 0 | G7: 0 | H7: 0 | I7: 0 | J7: 1 | K7: 2 | L7: 0.06 | M7: 0.17 | N7: 0.25 | O7: 1 | P7: 1.01 | Q7: 10 | R7: 0 | S7: 0 | T7: 0 | U7: 2.5 | V7: 0
A8: Jun | B8: 13 | C8: 9 | D8: 0 | E8: 3 | F8: 1 | G8: 0 | H8: 0 | I8: 0 | J8: 1 | K8: 2 | L8: 0.5 | M8: 0.29 | N8: 0.25 | O8: 1 | P8: 1.01 | Q8: 23 | R8: 0 | S8: 0 | T8: 0 | U8: 5.8 | V8: 0
A9: Jul | B9: 3 | C9: 2 | D9: 0 | E9: 0 | F9: 1 | G9: 0 | H9: 0 | I9: 0 | J9: 1 | K9: 2 | L9: 0.11 | M9: 0.25 | N9: 0.25 | O9: 1 | P9: 1.01 | Q9: 23 | R9: 3 | S9: 0 | T9: 0 | U9: 6.5 | V9: 0
A10: Aug | B10: 6 | C10: 3 | D10: 0 | E10: 0 | F10: 2 | G10: 1 | H10: 0 | I10: 0 | J10: 1 | K10: 2 | L10: 0.17 | M10: 0.3 | N10: 0.25 | O10: 1 | P10: 1.01 | Q10: 23 | R10: 9 | S10: 0 | T10: 0 | U10: 8 | V10: 0
A11: Sep | B11: 7 | C11: 3 | D11: 0 | E11: 1 | F11: 3 | G11: 0 | H11: 0 | I11: 0 | J11: 1 | K11: 2 | L11: 0.17 | M11: 0.34 | N11: 0.25 | O11: 1 | P11: 1.01 | Q11: 23 | R11: 16 | S11: 0 | T11: 0 | U11: 9.8 | V11: 0
A12: Oct | B12: 14 | C12: 12 | D12: 0 | E12: 1 | F12: 1 | G12: 0 | H12: 0 | I12: 0 | J12: 1 | K12: 2 | L12: 0.67 | M12: 0.42 | N12: 0.25 | O12: 1 | P12: 1.01 | Q12: 23 | R12: 16 | S12: 14 | T12: 0 | U12: 13.3 | V12: 0
A13: Nov | B13: 13 | C13: 8 | D13: 0 | E13: 1 | F13: 3 | G13: 1 | H13: 0 | I13: 0 | J13: 1 | K13: 2 | L13: 0.44 | M13: 0.45 | N13: 0.25 | O13: 1 | P13: 1.01 | Q13: 23 | R13: 16 | S13: 27 | T13: 0 | U13: 16.5 | V13: 0
A14: Dec | B14: 9 | C14: 8 | D14: 0 | E14: 0 | F14: 1 | G14: 0 | H14: 0 | I14: 0 | J14: 1 | K14: 2 | L14: 0.44 | M14: 0.48 | N14: 0.25 | O14: 1 | P14: 1.01 | Q14: 23 | R14: 16 | S14: 36 | T14: 0 | U14: 18.8 | V14: 0
A15: Jan | B15: 7 | C15: 5 | D15: 0 | E15: 2 | F15: 0 | G15: 0 | H15: 0 | I15: 0 | J15: 1 | K15: 2 | L15: 0.28 | M15: 0.37 | N15: 0.25 | O15: 1 | P15: 1.01 | Q15: 23 | R15: 17 | S15: 36 | T15: 7 | U15: 20.8 | V15: 0
A16: Feb | B16: 8 | C16: 6 | D16: 0 | E16: 0 | F16: 2 | G16: 0 | H16: 0 | I16: 0 | J16: 1 | K16: 2 | L16: 0.33 | M16: 0.36 | N16: 0.25 | O16: 1 | P16: 1.01 | Q16: 23 | R16: 17 | S16: 36 | T16: 14 | U16: 22.5 | V16: 0
A17: Mar | B17: 7 | C17: 7 | D17: 0 | E17: 0 | F17: 0 | G17: 0 | H17: 0 | I17: 0 | J17: 1 | K17: 2 | L17: 0.32 | M17: 0.36 | N17: 0.25 | O17: 1 | P17: 1.01 | Q17: 23 | R17: 17 | S17: 36 | T17: 21 | U17: 24.3 | V17: 0
A19: Woodstock 60782
A20: Month | B20: Defect Notice Count All | C20: Defect Notice Productioon | D20: Defect Notice In Process Machining | E20: Defect Notice Raw Material | F20: Defect Notice NPI/PPAP | G20: Defect Notice PPD Parts | H20: No Defect Claims Early Life Failure | I20: Green Target | J20: Yellow Target | K20: Red Target | L20: Production DPU | M20: Production Average FY DPU | N20: Green Target | O20: Yellow Target | P20: Red Target | Q20: Q1 | R20: Q2 | S20: Q3 | T20: Q4 | U20: Defect Notice Rolling Quarterly Average | V20: No Defect Claims Early Life Failure
A21: 2019 avg monthy defects | C21: 2.92 | L21: 0.17 | M21: 0.17 | N21: 0.25 | O21: 1 | P21: 1.01 | Q21: 11 | R21: 8 | S21: 5 | T21: 11 | U21: 8.8
A22: 2020 avg monthy defects | C22: 1.25 | L22: 0.08 | M22: 0.08 | N22: 0.25 | O22: 1 | P22: 1.01 | Q22: 5 | R22: 6 | S22: 3 | T22: 3 | U22: 3.8
A23: 2021 avg monthy defects | C23: 1.166 | L23: 0.08 | M23: 0.08 | N23: 0.25 | O23: 1 | P23: 1.01 | Q23: 1 | R23: 5 | S23: 4 | T23: 4 | U23: 3.5
A24: Apr | B24: 3 | C24: 3 | D24: 0 | E24: 0 | F24: 0 | G24: 0 | H24: 0 | I24: 0 | J24: 1 | K24: 2 | L24: 0.17 | M24: 0.17 | N24: 0.25 | O24: 1 | P24: 1.01 | Q24: 3 | R24: 0 | S24: 0 | T24: 0 | U24: 0.8 | V24: 0
A25: May | B25: 3 | C25: 3 | D25: 0 | E25: 0 | F25: 0 | G25: 0 | H25: 0 | I25: 0 | J25: 1 | K25: 2 | L25: 0.17 | M25: 0.17 | N25: 0.25 | O25: 1 | P25: 1.01 | Q25: 6 | R25: 0 | S25: 0 | T25: 0 | U25: 1.5 | V25: 0
A26: Jun | B26: 0 | C26: 0 | D26: 0 | E26: 0 | F26: 0 | G26: 0 | H26: 0 | I26: 0 | J26: 1 | K26: 2 | L26: 0 | M26: 0.12 | N26: 0.25 | O26: 1 | P26: 1.01 | Q26: 6 | R26: 0 | S26: 0 | T26: 0 | U26: 1.5 | V26: 0
A27: Jul | B27: 0 | C27: 0 | D27: 0 | E27: 0 | F27: 0 | G27: 0 | H27: 0 | I27: 0 | J27: 1 | K27: 2 | L27: 0 | M27: 0.09 | N27: 0.25 | O27: 1 | P27: 1.01 | Q27: 6 | R27: 0 | S27: 0 | T27: 0 | U27: 1.5 | V27: 0
A28: Aug | B28: 3 | C28: 3 | D28: 0 | E28: 0 | F28: 0 | G28: 0 | H28: 0 | I28: 0 | J28: 1 | K28: 2 | L28: 0.17 | M28: 0.13 | N28: 0.25 | O28: 1 | P28: 1.01 | Q28: 6 | R28: 3 | S28: 0 | T28: 0 | U28: 2.3 | V28: 0
A29: Sep | B29: 1 | C29: 1 | D29: 0 | E29: 0 | F29: 0 | G29: 0 | H29: 0 | I29: 0 | J29: 1 | K29: 2 | L29: 0.06 | M29: 0.15 | N29: 0.25 | O29: 1 | P29: 1.01 | Q29: 6 | R29: 4 | S29: 0 | T29: 0 | U29: 2.5 | V29: 0
A30: Oct | B30: 4 | C30: 4 | D30: 0 | E30: 0 | F30: 0 | G30: 0 | H30: 0 | I30: 0 | J30: 1 | K30: 2 | L30: 0.22 | M30: 0.17 | N30: 0.25 | O30: 1 | P30: 1.01 | Q30: 6 | R30: 4 | S30: 4 | T30: 0 | U30: 3.3 | V30: 0
A31: Nov | B31: 2 | C31: 2 | D31: 0 | E31: 0 | F31: 0 | G31: 0 | H31: 0 | I31: 0 | J31: 1 | K31: 2 | L31: 0.11 | M31: 0.13 | N31: 0.25 | O31: 1 | P31: 1.01 | Q31: 6 | R31: 2 | S31: 4 | T31: 0 | U31: 3 | V31: 0
A32: Dec | B32: 1 | C32: 1 | D32: 0 | E32: 0 | F32: 0 | G32: 0 | H32: 0 | I32: 0 | J32: 1 | K32: 2 | L32: 0.06 | M32: 0.12 | N32: 0.25 | O32: 1 | P32: 1.01 | Q32: 6 | R32: 2 | S32: 5 | T32: 0 | U32: 3.3 | V32: 0
A33: Jan | B33: 0 | C33: 0 | D33: 0 | E33: 0 | F33: 0 | G33: 0 | H33: 0 | I33: 0 | J33: 1 | K33: 2 | L33: 0 | M33: 0.1 | N33: 0.25 | O33: 1 | P33: 1.01 | Q33: 5 | R33: 4 | S33: 7 | T33: 0 | U33: 4 | V33: 0
A34: Feb | B34: 1 | C34: 1 | D34: 0 | E34: 0 | F34: 0 | G34: 0 | H34: 0 | I34: 0 | J34: 1 | K34: 2 | L34: 0.06 | M34: 0.1 | N34: 0.25 | O34: 1 | P34: 1.01 | Q34: 5 | R34: 4 | S34: 7 | T34: 1 | U34: 4.3 | V34: 0
A35: Mar | B35: 1 | C35: 1 | D35: 0 | E35: 0 | F35: 0 | G35: 0 | H35: 0 | I35: 0 | J35: 1 | K35: 2 | L35: 0.05 | M35: 0.09 | N35: 0.25 | O35: 1 | P35: 1.01 | Q35: 5 | R35: 4 | S35: 7 | T35: 2 | U35: 4.5 | V35: 0
B77: Studs off location
I79: video

Sheet pivot
A3: Location (as applicable) | B3: Cambridge
A4: Status | B4: (Multiple Items)
A5: Type | B5: Customer
A6: Customer | B6: Komatsu
A8: Row Labels | B8: Count of Internal CAR #
A9: 2025 | B9: 286
A10: 1 | B10: 13
A11: Axle | B11: 3
A12: Cab | B12: 3
A13: Control Box | B13: 2
A14: Deck | B14: 1
A15: Other | B15: 4
A16: 2 | B16: 40
A17: Axle | B17: 23
A18: Cab | B18: 7
A19: Control Box | B19: 1
A20: Deck | B20: 5
A21: Grill | B21: 1
A22: Tank | B22: 3
A23: 3 | B23: 31
A24: Axle | B24: 22
A25: Cab | B25: 2
A26: Control Box | B26: 1
A27: Deck | B27: 1
A28: Grill | B28: 2
A29: Other | B29: 3
A30: 4 | B30: 21
A31: Axle | B31: 17
A32: Cab | B32: 3
A33: Deck | B33: 1
A34: 5 | B34: 38
A35: Axle | B35: 25
A36: Cab | B36: 6
A37: Control Box | B37: 1
A38: Deck | B38: 2
A39: Other | B39: 4
A40: 6 | B40: 16
A41: Axle | B41: 10
A42: Cab | B42: 1
A43: Deck | B43: 4
...

Sheet Summary
A1: 58F2200054 | B1: 73
A2: 58B2200812 | B2: 26
A3: 58B2200813 | B3: 22
A4: X830027784 | B4: 19
A5: 58E2200234 | B5: 16
A6: 58B0207300 | B6: 8
A7: 58D2280002 | B7: 5
A8: 58B5421001 | B8: 4
A9: 58B5422835 | B9: 4
A10: 58B8040213 | B10: 4
A11: 58D2280003 | B11: 8
A12: 58E5452740 | B12: 4
... A34: X830035160 | B34: 2
A35: 58B0207003 | B35: 1 | F35: Axle | G35: 168
A36: 58B0240801 | B36: 1 | F36: Cab | G36: 50
A37: 58B2200054 | B37: 1 | F37: Deck | G37: 32
A38: 58B5405045 | B38: 1 | F38: Other | G38: 20
A39: 58B5431000 | B39: 1 | F39: Tank | G39: 10
A40: 58B5451602 | B40: 1 | F40: Control Box | G40: 9
A41: 58B5451603 | B41: 1 | F41: Grill | G41: 8
A42: 58B5453332 | B42: 1
A43: 58B5463860 | B43: 1
A44: 58B5463861 | B44: 1
A45: 58B5463951, 58B5463921 | B45: 1
A46: 58B5464630 | B46: 1
A47: 58B5464640 | B47: 1
A48: 58D5480362 | B48: 1
A49: 58E22000234 | B49: 1
A50: 58E2200132 | B50: 1
A51: 58E5400301 | B51: 1
A52: 58E5404775 | B52: 1 | F52: Weld | G52: 213
A53: 58E5408924 | B53: 1 | F53: Machining | G53: 21
A54: 58E5423540 | B54: 1 | F54: Assembly | G54: 18
A55: 58E5430646 | B55: 1 | F55: Paint | G55: 18
A56: 58E5430653 | B56: 1 | F56: Shipping | G56: 11
A57: 58E5430663 | B57: 1 | F57: Weld/Paint | G57: 7
A58: 58E545291 | B58: 1 | F58: Final Assembly | G58: 2
A59: 58E8050642, 58E8050632 | B59: 1 | F59: Laser /Plasma | G59: 2
A60: 58E8055050 | B60: 1 | F60: Engineering | G60: 1
A61: 58F0150571 | B61: 1 | F61: Final Assembly / Shipping | G61: 1
...

Sheet CAR LOG
G1: Corrective Action Log | AE1: Corrective Action Form | AF1: GDLS PDF | AG1: Strat/Wood PDF | AH1: Cambridge PDF
AH2: <<< Unhide previous columns for other date targets as needed
A3: Location (as applicable) | B3: Status | C3: Internal CAR # | D3: Incidence Type | E3: Type | F3: Category | G3: Received Date | H3: Month | I3: Year | J3: Part Number | K3: Part Description | L3: Part Family | M3: Reference #'s (Cust. CAR #, Stop Tag #, Audit NC #) | N3: Customer | O3: email | P3: 200 Series | Q3: 800 Series | R3: Komatsu Tracking | S3: Work Order # | T3: Manufacture Date | U3: Quantity | V3: Problem Description | W3: Department Responsible | X3: Defect Category | Y3: Champion | Z3: Containment Complete? | AA3: Corrective Action Prevention | AB3: Corrective Action Detection | AC3: Proposed Cost | AD3: Cost Approved? | AE3: Initial Resp. | AF3: Final Resp. Due Date | AG3: Completed Resp. Actual | AH3: Follow Up Dates | AI3: # Days Ongoing | AJ3: # Days to Close | AK3: Closed Date | AL3: Employee ID | AM3: RMA # | AN3: Follow up items: | AO3: Contact | AP3: Contact2 | AQ3: Contact3 | AR3: Contact4 | AS3: Debit Cost | AT3: Comments
A4: Cambridge | B4: Closed | C4: 25-013 | D4: Initial Rejection | E4: Customer | F4: 8D - Customer | G4: 45672 | H4: =MONTH(Table1[[#This Row],[Received Date]]) -> 1 | I4: =YEAR(Table1[[#This Row],[Received Date]]) -> 2025 | J4: SP-3132 | K4: Chassis | L4: =IF(ISNUMBER(SEARCH("Axle",K4)),"Axle", IF(ISNUMBER(SEARCH("Deck",K4)),"Deck", IF(ISNUMBER(SEARCH("Cab",K4)),"Cab", IF(ISNUMBER(SEARCH("Tank",K4)),"Tank", IF(ISNUMBER(SEARCH("Grill",K4)),"Grill", IF(ISNUMBER(SEARCH("Control",K4)),"Control Box", "Other")))))) -> Other | M4: N/A | N4: Midland | O4: =IF(ISNUMBER(SEARCH("mail",M4)), "Email", "") | P4: =IF(AND(200000<M4,M4<299999), 2, "") | Q4: =IF(AND(800000<M4,M4<899999), 8, "") | R4: =IF(OR(O4="Email",P4=2, Q4=8), "don't count", "count") -> count | S4: N/A | T4: 46015 | U4: 1 | V4: The frame is missing a latch Item no. 13 on drawing SP-3135 (M5075) for holding the side door open on the machine | W4: Weld | X4: Missing Component | Y4: QA | AB4: Every sub-component must be verifed for presence after welding and Twyn inspection should also be peformed at the end of welding process. Twyn was not performed on this and will be going forward. | AI4: =IF(ISBLANK(G4), "",IF(ISBLANK(AK4), TODAY()-G4, "Closed")) -> 362 | AJ4: =IF(ISBLANK(G4),"", IF(ISBLANK(AK4), "Pending", DATEDIF(G4,AK4,"d"))) -> Pending
A5: Cambridge | B5: Follow up | C5: 25-155 | D5: Initial Rejection | E5: Customer | F5: 8D - Customer | G5: 45796 | H5: =MONTH(Table1[[#This Row],[Received Date]]) -> 5 | I5: =YEAR(Table1[[#This Row],[Received Date]]) -> 2025 | J5: X830027784 | K5: Cab G | L5: =IF(ISNUMBER(SEARCH("Axle",K5)),"Axle", IF(ISNUMBER(SEARCH("Deck",K5)),"Deck", IF(ISNUMBER(SEARCH("Cab",K5)),"Cab", IF(ISNUMBER(SEARCH("Tank",K5)),"Tank", IF(ISNUMBER(SEARCH("Grill",K5)),"Grill", IF(ISNUMBER(SEARCH("Control",K5)),"Control Box", "Other")))))) -> Cab | M5: 517599 | N5: Komatsu | O5: =IF(ISNUMBER(SEARCH("mail",M5)), "Email", "") | P5: =IF(AND(200000<M5,M5<299999), 2, "") | Q5: =IF(AND(800000<M5,M5<899999), 8, "") | R5: =IF(OR(O5="Email",P5=2, Q5=8), "don't count", "count") -> count | S5: 506224 | T5: 2025-Mar | U5: 1 | V5: PB9923 windshield wiper motor has dead short causing fuse to pop when powered on | W5: Assembly | X5: Poor Function | Y5: Sibin Siva | Z5: Y | AA5: This has been supplied to us and all wiper motors are to be certified by supplier | AB5: Use the updated Cab assembly checklist (FRM-MF-065-C) to include additional electrical run test verification on all wiper motors | AI5: =IF(ISBLANK(G5), "",IF(ISBLANK(AK5), TODAY()-G5, "Closed")) -> 238 | AJ5: =IF(ISBLANK(G5),"", IF(ISBLANK(AK5), "Pending", DATEDIF(G5,AK5,"d"))) -> Pending | AT5: 46000
A6: Cambridge | B6: Closed | C6: 25-169 | D6: Initial Rejection | E6: Customer | F6: 8D - Internal | G6: 45810 | H6: =MONTH(Table1[[#This Row],[Received Date]]) -> 6 | I6: =YEAR(Table1[[#This Row],[Received Date]]) -> 2025 | J6: 58D2280002 | K6: Axle Housing STR | L6: =IF(ISNUMBER(SEARCH("Axle",K6)),"Axle", IF(ISNUMBER(SEARCH("Deck",K6)),"Deck", IF(ISNUMBER(SEARCH("Cab",K6)),"Cab", IF(ISNUMBER(SEARCH("Tank",K6)),"Tank", IF(ISNUMBER(SEARCH("Grill",K6)),"Grill", IF(ISNUMBER(SEARCH("Control",K6)),"Control Box", "Other")))))) -> Axle | M6: 898960 | N6: Komatsu | O6: =IF(ISNUMBER(SEARCH("mail",M6)), "Email", "") | P6: =IF(AND(200000<M6,M6<299999), 2, "") | Q6: =IF(AND(800000<M6,M6<899999), 8, "") -> 8 | R6: =IF(OR(O6="Email",P6=2, Q6=8), "don't count", "count") -> don't count | S6: 508787 | T6: 45802 | U6: 1 | V6: Several areas of poor weld quality. will need reworked prior to use. areas of poor weld quality marked on the part. Debit 2400 only | W6: Weld | X6: Weld Defects | Y6: Sibin Siva | Z6: Y | AA6: Welder Must weld to the customer spec. All corners needs to be wrapped and blended properly.use v-wac gauge for measuring undercut | AB6: Always use the appropriate welding parameters to measure under cut and make sure they are in spec. All corners needs to be wrapped and blended properly. | AC6: N/A | AD6: N/A | AI6: =IF(ISBLANK(G6), "",IF(ISBLANK(AK6), TODAY()-G6, "Closed")) -> 224 | AJ6: =IF(ISBLANK(G6),"", IF(ISBLANK(AK6), "Pending", DATEDIF(G6,AK6,"d"))) -> Pending
A7: Cambridge | B7: Closed | C7: 25-187 | D7: Initial Rejection | E7: Customer | F7: 8D - Internal | G7: 45832 | H7: =MONTH(Table1[[#This Row],[Received Date]]) -> 6 | I7: =YEAR(Table1[[#This Row],[Received Date]]) -> 2025 | J7: 58B2200812 | K7: Axle Housing STR | L7: =IF(ISNUMBER(SEARCH("Axle",K7)),"Axle", IF(ISNUMBER(SEARCH("Deck",K7)),"Deck", IF(ISNUMBER(SEARCH("Cab",K7)),"Cab", IF(ISNUMBER(SEARCH("Tank",K7)),"Tank", IF(ISNUMBER(SEARCH("Grill",K7)),"Grill", IF(ISNUMBER(SEARCH("Control",K7)),"Control Box", "Other")))))) -> Axle | M7: 517857 | N7: Komatsu | O7: =IF(ISNUMBER(SEARCH("mail",M7)), "Email", "") | P7: =IF(AND(200000<M7,M7<299999), 2, "") | Q7: =IF(AND(800000<M7,M7<899999), 8, "") | R7: =IF(OR(O7="Email",P7=2, Q7=8), "don't count", "count") -> count | S7: 509443 | T7: 45802 | U7: 1 | V7: During assembly at G&D axle was found with rust/debris in ports of 58B6010020 manifold, plastic caps do not provid proper protection from contamination. 58B6010020 print list eng std 4.93.003 which lists plugs that should be installed in ports to prevent contamination. Unknown why supplier is not installing plugs per engineering specs,many past defects debit 42 only | W7: Paint | X7: rust | Y7: Jatinder Singh | Z7: Y | AA7: Full protection required using caps. RP must be applied prior to putting caps | AB7: Please make sure threaded holes and machines surfaces always protected from paint and rust. RP must be applied prior to putting caps and needs to be verified | AC7: N/A | AD7: N/A | AI7: =IF(ISBLANK(G7), "",IF(ISBLANK(AK7), TODAY()-G7, "Closed")) -> 202 | AJ7: =IF(ISBLANK(G7),"", IF(ISBLANK(AK7), "Pending", DATEDIF(G7,AK7,"d"))) -> Pending
A8: Cambridge | B8: Open | C8: 25-374 | D8: Internal Audit | E8: Audit | F8: Audit CA | G8: 46010 | H8: =MONTH(Table1[[#This Row],[Received Date]]) -> 12 | I8: =YEAR(Table1[[#This Row],[Received Date]]) -> 2025 | J8: NA | K8: Product/Process Validation Receiving | L8: =IF(ISNUMBER(SEARCH("Axle",K8)),"Axle", IF(ISNUMBER(SEARCH("Deck",K8)),"Deck", IF(ISNUMBER(SEARCH("Cab",K8)),"Cab", IF(ISNUMBER(SEARCH("Tank",K8)),"Tank", IF(ISNUMBER(SEARCH("Grill",K8)),"Grill", IF(ISNUMBER(SEARCH("Control",K8)),"Control Box", "Other")))))) -> Other | M8: NA | N8: Internal | O8: =IF(ISNUMBER(SEARCH("mail",M8)), "Email", "") | P8: =IF(AND(200000<M8,M8<299999), 2, "") | Q8: =IF(AND(800000<M8,M8<899999), 8, "") | R8: NA | S8: NA | T8: NA | U8: NA | V8: Receiver not verify MTR per process map Receiver not scan paint CoA per process map Supplier PPAP not identified using QA-715 per process map | W8: Receiving | Y8: Laura Ray | AI8: =IF(ISBLANK(G8), "",IF(ISBLANK(AK8), TODAY()-G8, "Closed")) -> 24 | AJ8: =IF(ISBLANK(G8),"", IF(ISBLANK(AK8), "Pending", DATEDIF(G8,AK8,"d"))) -> Pending
A9: Cambridge | B9: Open | C9: 25-378 | D9: Internal Audit | E9: Audit | F9: OFI | G9: 46011 | H9: NA | I9: Product/Process Validation Receiving | J9: PC | K9: Training | L9: =IF(ISNUMBER(SEARCH("Axle",K9)),"Axle", IF(ISNUMBER(SEARCH("Deck",K9)),"Deck", IF(ISNUMBER(SEARCH("Cab",K9)),"Cab", IF(ISNUMBER(SEARCH("Tank",K9)),"Tank", IF(ISNUMBER(SEARCH("Grill",K9)),"Grill", IF(ISNUMBER(SEARCH("Control",K9)),"Control Box", "Other")))))) -> Other | M9: NA | N9: Internal | O9: =IF(ISNUMBER(SEARCH("mail",M9)), "Email", "") | P9: =IF(AND(200000<M9,M9<299999), 2, "") | Q9: =IF(AND(800000<M9,M9<899999), 8, "") | R9: NA | S9: NA | T9: NA | U9: NA | V9: Training Form names should be updated per markup to reflect the new form # in use in fusion. Process is followed | Y9: Sebastian | AI9: =IF(ISBLANK(G9), "",IF(ISBLANK(AK9), TODAY()-G9, "Closed")) -> 23 | AJ9: =IF(ISBLANK(G9),"", IF(ISBLANK(AK9), "Pending", DATEDIF(G9,AK9,"d"))) -> Pending
A10: Cambridge | B10: Open | C10: 25-377 | D10: Internal Audit | E10: Audit | F10: OFI | G10: 46011 | H10: NA | I10: Product/Process Validation Receiving | J10: PC | K10: Change Control | L10: =IF(ISNUMBER(SEARCH("Axle",K10)),"Axle", IF(ISNUMBER(SEARCH("Deck",K10)),"Deck", IF(ISNUMBER(SEARCH("Cab",K10)),"Cab", IF(ISNUMBER(SEARCH("Tank",K10)),"Tank", IF(ISNUMBER(SEARCH("Grill",K10)),"Grill", IF(ISNUMBER(SEARCH("Control",K10)),"Control Box", "Other")))))) -> Control Box | M10: NA | N10: Internal | O10: NA | P10: NA | Q10: =IF(AND(800000<M10,M10<899999), 8, "") | R10: NA | S10: NA | T10: NA | U10: NA | V10: ECN tab 2 is not use in Cambridge. Tab 2 is used in stratford FRM EN-007 (neither location uses this) consider updating or evaluating do we want to use this form. | W10: Engineering | Y10: Jason | AI10: =IF(ISBLANK(G10), "",IF(ISBLANK(AK10), TODAY()-G10, "Closed")) -> 23 | AJ10: =IF(ISBLANK(G10),"", IF(ISBLANK(AK10), "Pending", DATEDIF(G10,AK10,"d"))) -> Pending
A11: Cambridge | B11: Open | C11: 25-376 | D11: Internal Audit | E11: Audit | F11: OFI | G11: 46011 | H11: NA | I11: Product/Process Validation Receiving | J11: PC | K11: Shipping | L11: =IF(ISNUMBER(SEARCH("Axle",K11)),"Axle", IF(ISNUMBER(SEARCH("Deck",K11)),"Deck", IF(ISNUMBER(SEARCH("Cab",K11)),"Cab", IF(ISNUMBER(SEARCH("Tank",K11)),"Tank", IF(ISNUMBER(SEARCH("Grill",K11)),"Grill", IF(ISNUMBER(SEARCH("Control",K11)),"Control Box", "Other")))))) -> Other | M11: NA | N11: Internal | O11: NA | P11: NA | Q11: =IF(AND(800000<M11,M11<899999), 8, "") | R11: NA | S11: NA | T11: NA | U11: NA | V11: Process is followed but wording is different. Procedure states Pack list vs Pack slips. CRS is that CSR Customer Service Rep. Receive other shipping documents. It is assumed this means PPAP or Deviation documents. In process flow elizibeth currently files copy per PRO 1.1 and Invoices customer per WI-12.1 . See scanned notes | W11: Shipping | Y11: Laura Ray | AI11: =IF(ISBLANK(G11), "",IF(ISBLANK(AK11), TODAY()-G11, "Closed")) -> 23 | AJ11: =IF(ISBLANK(G11),"", IF(ISBLANK(AK11), "Pending", DATEDIF(G11,AK11,"d"))) -> Pending
A12: Cambridge | B12: Open | C12: 25-375 | D12: Internal Audit | E12: Audit | F12: OFI | G12: 46010 | H12: =MONTH(Table1[[#This Row],[Received Date]]) -> 12 | I12: =YEAR(Table1[[#This Row],[Received Date]]) -> 2025 | J12: NA | K12: Product/Process Validation Receiving | L12: =IF(ISNUMBER(SEARCH("Axle",K12)),"Axle", IF(ISNUMBER(SEARCH("Deck",K12)),"Deck", IF(ISNUMBER(SEARCH("Cab",K12)),"Cab", IF(ISNUMBER(SEARCH("Tank",K12)),"Tank", IF(ISNUMBER(SEARCH("Grill",K12)),"Grill", IF(ISNUMBER(SEARCH("Control",K12)),"Control Box", "Other")))))) -> Other | M12: NA | N12: Internal | O12: =IF(ISNUMBER(SEARCH("mail",M12)), "Email", "") | P12: =IF(AND(200000<M12,M12<299999), 2, "") | Q12: =IF(AND(800000<M12,M12<899999), 8, "") | R12: NA | S12: NA | T12: NA | U12: NA | V12: After QA finish inspection, measurement value is recorded on drawing, there is no sign off on drawing to show who performed the task and when the inspectitoin was done. The scanned drawing saved in foldder, there is no clear link supliere PO | W12: QA | Y12: Yingman Cheng | AI12: =IF(ISBLANK(G12), "",IF(ISBLANK(AK12), TODAY()-G12, "Closed")) -> 24 | AJ12: =IF(ISBLANK(G12),"", IF(ISBLANK(AK12), "Pending", DATEDIF(G12,AK12,"d"))) -> Pending
L13: =IF(ISNUMBER(SEARCH("Axle",K13)),"Axle", IF(ISNUMBER(SEARCH("Deck",K13)),"Deck", IF(ISNUMBER(SEARCH("Cab",K13)),"Cab", IF(ISNUMBER(SEARCH("Tank",K13)),"Tank", IF(ISNUMBER(SEARCH("Grill",K13)),"Grill", IF(ISNUMBER(SEARCH("Control",K13)),"Control Box", "Other")))))) -> Other
A14: Cambridge | B14: Closed | C14: 25-001 | D14: Initial Rejection | E14: Customer | F14: Log Only | G14: 45663 | H14: =MONTH(Table1[[#This Row],[Received Date]]) -> 1 | I14: =YEAR(Table1[[#This Row],[Received Date]]) -> 2025 | J14: 58B2200812 | K14: Axle, Housing STR | L14: =IF(ISNUMBER(SEARCH("Axle",K14)),"Axle", IF(ISNUMBER(SEARCH("Deck",K14)),"Deck", IF(ISNUMBER(SEARCH("Cab",K14)),"Cab", IF(ISNUMBER(SEARCH("Tank",K14)),"Tank", IF(ISNUMBER(SEARCH("Grill",K14)),"Grill", IF(ISNUMBER(SEARCH("Control",K14)),"Control Box", "Other")))))) -> Axle | M14: 516792 | N14: Komatsu | O14: =IF(ISNUMBER(SEARCH("mail",M14)), "Email", "") | P14: =IF(AND(200000<M14,M14<299999), 2, "") | Q14: =IF(AND(800000<M14,M14<899999), 8, "") | R14: =IF(OR(O14="Email",P14=2, Q14=8), "don't count", "count") -> count | S14: 504138 | T14: 45649 | U14: 1 | V14: During assembly at G&D 58b2201620 hatch door was found not latching closed properly. Latch will not grab keeper. 2 different hatch doors tried with same result. Hatch door measurement o mm checks ok. Unable to measure axle dimension of 709.7mm. EL0851 possibly welded off location for keeper. Order 1 pc of EL0851 from supplier. | W14: Weld | X14: Off Location | Y14: QA | AB14: Use the fixture in appropriate way and verify the measurments afterwards.Debit $150 | AE14: QA | AF14: QA | AG14: QA | AI14: =IF(ISBLANK(G14), "",IF(ISBLANK(AK14), TODAY()-G14, "Closed")) -> 371 | AJ14: =IF(ISBLANK(G14),"", IF(ISBLANK(AK14), "Pending", DATEDIF(G14,AK14,"d"))) -> Pending
A15: Cambridge | B15: Cancelled | C15: 25-002 | D15: Initial Rejection | E15: Customer | F15: Log Only | G15: 45659 | H15: =MONTH(Table1[[#This Row],[Received Date]]) -> 1 | I15: =YEAR(Table1[[#This Row],[Received Date]]) -> 2025 | J15: 58B5422835 | K15: Control box | L15: =IF(ISNUMBER(SEARCH("Axle",K15)),"Axle", IF(ISNUMBER(SEARCH("Deck",K15)),"Deck", IF(ISNUMBER(SEARCH("Cab",K15)),"Cab", IF(ISNUMBER(SEARCH("Tank",K15)),"Tank", IF(ISNUMBER(SEARCH("Grill",K15)),"Grill", IF(ISNUMBER(SEARCH("Control",K15)),"Control Box", "Other")))))) -> Control Box | M15: 954246 | N15: Komatsu | O15: =IF(ISNUMBER(SEARCH("mail",M15)), "Email", "") | P15: =IF(AND(200000<M15,M15<299999), 2, "") | Q15: =IF(AND(800000<M15,M15<899999), 8, "") | R15: =IF(OR(O15="Email",P15=2, Q15=8), "don't count", "count") -> count | S15: 501223 | T15: N/A | U15: 1 | V15: When checking for water damage the door came off hinges and dropped the door causing some bent . | W15: Mateial Handling | X15: Damaged | Y15: QA | AB15: This should not be on us as it was mis-handled by Komatsu employees. | AI15: =IF(ISBLANK(G15), "",IF(ISBLANK(AK15), TODAY()-G15, "Closed")) -> 375 | AJ15: =IF(ISBLANK(G15),"", IF(ISBLANK(AK15), "Pending", DATEDIF(G15,AK15,"d"))) -> Pending
A16: Cambridge | B16: Closed | C16: 25-003 | D16: Initial Rejection | E16: Customer | F16: Log Only | G16: 45663 | H16: =MONTH(Table1[[#This Row],[Received Date]]) -> 1 | I16: =YEAR(Table1[[#This Row],[Received Date]]) -> 2025 | J16: 58B5422835 | K16: Control box | L16: =IF(ISNUMBER(SEARCH("Axle",K16)),"Axle", IF(ISNUMBER(SEARCH("Deck",K16)),"Deck", IF(ISNUMBER(SEARCH("Cab",K16)),"Cab", IF(ISNUMBER(SEARCH("Tank",K16)),"Tank", IF(ISNUMBER(SEARCH("Grill",K16)),"Grill", IF(ISNUMBER(SEARCH("Control",K16)),"Control Box", "Other")))))) -> Control Box | M16: 516427 | N16: Komatsu | O16: =IF(ISNUMBER(SEARCH("mail",M16)), "Email", "") | P16: =IF(AND(200000<M16,M16<299999), 2, "") | Q16: =IF(AND(800000<M16,M16<899999), 8, "") | R16: =IF(OR(O16="Email",P16=2, Q16=8), "don't count", "count") -> count | S16: 493151 | T16: 45801 | U16: 1 | V16: Right hand side mounting plate is welded on approx 120mm off. Spec: 1321.1mm & actual measurement is 1200mm. | W16: Weld | X16: Off Location | Y16: QA | AB16: 100% Twyn inspection on all cabinets as per QA 25-002 | AI16: =IF(ISBLANK(G16), "",IF(ISBLANK(AK16), TODAY()-G16, "Closed")) -> 371 | AJ16: =IF(ISBLANK(G16),"", IF(ISBLANK(AK16), "Pending", DATEDIF(G16,AK16,"d"))) -> Pending
A17: Cambridge | B17: Cancelled | C17: 25-004 | D17: Pull stock / Purge | E17: Customer | F17: Log Only | G17: 45663 | H17: =MONTH(Table1[[#This Row],[Received Date]]) -> 1 | I17: =YEAR(Table1[[#This Row],[Received Date]]) -> 2025 | J17: 58F8000884 | K17: Grille Str. | L17: =IF(ISNUMBER(SEARCH("Axle",K17)),"Axle", IF(ISNUMBER(SEARCH("Deck",K17)),"Deck", IF(ISNUMBER(SEARCH("Cab",K17)),"Cab", IF(ISNUMBER(SEARCH("Tank",K17)),"Tank", IF(ISNUMBER(SEARCH("Grill",K17)),"Grill", IF(ISNUMBER(SEARCH("Control",K17)),"Control Box", "Other")))))) -> Grill | M17: 898398 | N17: Komatsu | O17: =IF(ISNUMBER(SEARCH("mail",M17)), "Email", "") | P17: =IF(AND(200000<M17,M17<299999), 2, "") | Q17: =IF(AND(800000<M17,M17<899999), 8, "") -> 8 | R17: =IF(OR(O17="Email",P17=2, Q17=8), "don't count", "count") -> don't count | S17: N/A | T17: N/A | U17: 1 | V17: Wrong cap screw welded on part for radiator cap to bolt on. Should be .875" long and founds ome of 0.750". Same as defect 516729 (24-358). | W17: Weld | X17: Wrong Component | Y17: QA | AB17: Material handlers: Make sure right parts are picked as per work order. Verify the length & thread size of studs, nuts and cap screws as it can be mis-interptered easily. QA 24-178. Debit $7890.05 | AI17: =IF(ISBLANK(G17), "",IF(ISBLANK(AK17), TODAY()-G17, "Closed")) -> 371 | AJ17: =IF(ISBLANK(G17),"", IF(ISBLANK(AK17), "Pending", DATEDIF(G17,AK17,"d"))) -> Pending
A18: Cambridge | B18: Closed | C18: 25-005 | D18: Initial Rejection | E18: Customer | F18: Log Only | G18: 45664 | H18: =MONTH(Table1[[#This Row],[Received Date]]) -> 1 | I18: =YEAR(Table1[[#This Row],[Received Date]]) -> 2025 | J18: 58F5431051 | K18: Platfrom A, lH Deck str. | L18: =IF(ISNUMBER(SEARCH("Axle",K18)),"Axle", IF(ISNUMBER(SEARCH("Deck",K18)),"Deck", IF(ISNUMBER(SEARCH("Cab",K18)),"Cab", IF(ISNUMBER(SEARCH("Tank",K18)),"Tank", IF(ISNUMBER(SEARCH("Grill",K18)),"Grill", IF(ISNUMBER(SEARCH("Control",K18)),"Control Box", "Other")))))) -> Deck | M18: 954252 | N18: Komatsu | O18: =IF(ISNUMBER(SEARCH("mail",M18)), "Email", "") | P18: =IF(AND(200000<M18,M18<299999), 2, "") | Q18: =IF(AND(800000<M18,M18<899999), 8, "") | R18: =IF(OR(O18="Email",P18=2, Q18=8), "don't count", "count") -> count | S18: 503489 | T18: N/A | U18: 1 | V18: PPAP part. Welds does not meet the print spec.Debit $14085.22 | W18: Weld | X18: PPAP | AB18: Okay for wash magnets needs tro be used to signal its ready for wash. Do not wash any PPAP part without if these magnets are not put on the part by quality | AI18: =IF(ISBLANK(G18), "",IF(ISBLANK(AK18), TODAY()-G18, "Closed")) -> 370 | AJ18: =IF(ISBLANK(G18),"", IF(ISBLANK(AK18), "Pending", DATEDIF(G18,AK18,"d"))) -> Pending
A19: Cambridge | B19: Closed | C19: 25-006 | D19: Initial Rejection | E19: Customer | F19: Log Only | G19: 45666 | H19: =MONTH(Table1[[#This Row],[Received Date]]) -> 1 | I19: =YEAR(Table1[[#This Row],[Received Date]]) -> 2025 | J19: 58B5422835 | K19: Control box | L19: =IF(ISNUMBER(SEARCH("Axle",K19)),"Axle", IF(ISNUMBER(SEARCH("Deck",K19)),"Deck", IF(ISNUMBER(SEARCH("Cab",K19)),"Cab", IF(ISNUMBER(SEARCH("Tank",K19)),"Tank", IF(ISNUMBER(SEARCH("Grill",K19)),"Grill", IF(ISNUMBER(SEARCH("Control",K19)),"Control Box", "Other")))))) -> Control Box | M19: 954256 | N19: Komatsu | O19: =IF(ISNUMBER(SEARCH("mail",M19)), "Email", "") | P19: =IF(AND(200000<M19,M19<299999), 2, "") | Q19: =IF(AND(800000<M19,M19<899999), 8, "") | R19: =IF(OR(O19="Email",P19=2, Q19=8), "don't count", "count") -> count | S19: 501048 | T19: 45985 | U19: 1 | V19: Water leakage between the walls. Debit $8334.20 only | W19: Wash | X19: water leakage | Y19: QA | AB19: Kan to try wiping with alcohol instead of washing. Wash only outside and wipe down inside with alcohol. | AI19: =IF(ISBLANK(G19), "",IF(ISBLANK(AK19), TODAY()-G19, "Closed")) -> 368 | AJ19: =IF(ISBLANK(G19),"", IF(ISBLANK(AK19), "Pending", DATEDIF(G19,AK19,"d"))) -> Pending
A20: Cambridge | B20: Closed | C20: 25-007 | D20: Initial Rejection | E20: Customer | F20: Log Only | G20: 45666 | H20: =MONTH(Table1[[#This Row],[Received Date]]) -> 1 | I20: =YEAR(Table1[[#This Row],[Received Date]]) -> 2025 | J20: X830027784 | K20: Cab G, Purchased | L20: =IF(ISNUMBER(SEARCH("Axle",K20)),"Axle", IF(ISNUMBER(SEARCH("Deck",K20)),"Deck", IF(ISNUMBER(SEARCH("Cab",K20)),"Cab", IF(ISNUMBER(SEARCH("Tank",K20)),"Tank", IF(ISNUMBER(SEARCH("Grill",K20)),"Grill", IF(ISNUMBER(SEARCH("Control",K20)),"Control Box", "Other")))))) -> Cab | M20: 516816 | N20: Komatsu | O20: =IF(ISNUMBER(SEARCH("mail",M20)), "Email", "") | P20: =IF(AND(200000<M20,M20<299999), 2, "") | Q20: =IF(AND(800000<M20,M20<899999), 8, "") | R20: =IF(OR(O20="Email",P20=2, Q20=8), "don't count", "count") -> count | S20: 502242 | T20: 45985 | U20: 1 | V20: 58E-54-10682 trim bracket is off location inside of cab causing RH side panel 58B-54-70770 to not fit properly. Trim bracket should measure 345.1mm from tapped hole in rops frame. Actual measurement is approx. 341mm | W20: Weld | X20: Off Location | AB20: QA 25-005 to use fixture. Debit $450.00 only | AI20: =IF(ISBLANK(G20), "",IF(ISBLANK(AK20), TODAY()-G20, "Closed")) -> 368 | AJ20: =IF(ISBLANK(G20),"", IF(ISBLANK(AK20), "Pending", DATEDIF(G20,AK20,"d"))) -> Pending
A21: Cambridge | B21: Closed | C21: 25-008 | D21: Initial Rejection | E21: Customer | F21: Log Only | G21: 45666 | H21: =MONTH(Table1[[#This Row],[Received Date]]) -> 1 | I21: =YEAR(Table1[[#This Row],[Received Date]]) -> 2025 | J21: SP-10 | K21: Chassis | L21: =IF(ISNUMBER(SEARCH("Axle",K21)),"Axle", IF(ISNUMBER(SEARCH("Deck",K21)),"Deck", IF(ISNUMBER(SEARCH("Cab",K21)),"Cab", IF(ISNUMBER(SEARCH("Tank",K21)),"Tank", IF(ISNUMBER(SEARCH("Grill",K21)),"Grill", IF(ISNUMBER(SEARCH("Control",K21)),"Control Box", "Other")))))) -> Other | M21: N/A | N21: Midland | O21: =IF(ISNUMBER(SEARCH("mail",M21)), "Email", "") | P21: =IF(AND(200000<M21,M21<299999), 2, "") | Q21: =IF(AND(800000<M21,M21<899999), 8, "") | R21: =IF(OR(O21="Email",P21=2, Q21=8), "don't count", "count") -> count | S21: N/A | T21: 46015 | U21: 1 | V21: The left side operator console mount socket (SP-134) is not square to the deck of the machine. | W21: Weld | X21: Off Location | Y21: QA | AB21: QA issued stating team member must verify squarness. Mount Sockets should be checked for square after welding and do not apply excessive heat input during hollow pipe welding. | AI21: =IF(ISBLANK(G21), "",IF(ISBLANK(AK21), TODAY()-G21, "Closed")) -> 368 | AJ21: =IF(ISBLANK(G21),"", IF(ISBLANK(AK21), "Pending", DATEDIF(G21,AK21,"d"))) -> Pending
A22: Cambridge | B22: In Dispute | C22: 25-011 | D22: Initial Rejection | E22: Customer | F22: Log Only | G22: 45671 | H22: =MONTH(Table1[[#This Row],[Received Date]]) -> 1 | I22: =YEAR(Table1[[#This Row],[Received Date]]) -> 2025 | J22: 58E5430663 | K22: Handle, Door Grab RH | L22: =IF(ISNUMBER(SEARCH("Axle",K22)),"Axle", IF(ISNUMBER(SEARCH("Deck",K22)),"Deck", IF(ISNUMBER(SEARCH("Cab",K22)),"Cab", IF(ISNUMBER(SEARCH("Tank",K22)),"Tank", IF(ISNUMBER(SEARCH("Grill",K22)),"Grill", IF(ISNUMBER(SEARCH("Control",K22)),"Control Box", "Other")))))) -> Other | M22: 310655 | N22: Komatsu | O22: =IF(ISNUMBER(SEARCH("mail",M22)), "Email", "") | P22: =IF(AND(200000<M22,M22<299999), 2, "") | Q22: =IF(AND(800000<M22,M22<899999), 8, "") | R22: =IF(OR(O22="Email",P22=2, Q22=8), "don't count", "count") -> count | S22: N/A | T22: N/A | U22: 31 | V22: Wrong part # is printed on the sticker thats taped to the part. Part #58E-54-30662 is on the sticker, but should be part #58E-54-30663. | W22: Final Assembly / Shipping | X22: Wrong Product ID | Y22: QA | AB22: Ensure the right lable is used on the part as the the print | AI22: =IF(ISBLANK(G22), "",IF(ISBLANK(AK22), TODAY()-G22, "Closed")) -> 363 | AJ22: =IF(ISBLANK(G22),"", IF(ISBLANK(AK22), "Pending", DATEDIF(G22,AK22,"d"))) -> Pending
A23: Cambridge | B23: Closed | C23: 25-012 | D23: Initial Rejection | E23: Customer | F23: Log Only | G23: 45671 | H23: =MONTH(Table1[[#This Row],[Received Date]]) -> 1 | I23: =YEAR(Table1[[#This Row],[Received Date]]) -> 2025 | J23: 58F0150571 | K23: Muffler A., Exhaust | L23: =IF(ISNUMBER(SEARCH("Axle",K23)),"Axle", IF(ISNUMBER(SEARCH("Deck",K23)),"Deck", IF(ISNUMBER(SEARCH("Cab",K23)),"Cab", IF(ISNUMBER(SEARCH("Tank",K23)),"Tank", IF(ISNUMBER(SEARCH("Grill",K23)),"Grill", IF(ISNUMBER(SEARCH("Control",K23)),"Control Box", "Other")))))) -> Other | M23: 310657 | N23: Komatsu | O23: =IF(ISNUMBER(SEARCH("mail",M23)), "Email", "") | P23: =IF(AND(200000<M23,M23<299999), 2, "") | Q23: =IF(AND(800000<M23,M23<899999), 8, "") | R23: =IF(OR(O23="Email",P23=2, Q23=8), "don't count", "count") -> count | S23: 499257 | T23: 45985 | U23: 1 | V23: Wrong part sent by supplier. Part #58F-02-50571 was ordered, but part #58F-02-50570 was received. This was a mistake from our side and it got resolved in Nov-2024. see emails in the CAR folder | W23: Shipping | X23: Wrong Part | Y23: QA | AB23: Verify the part ID with the packaing slip beofre putting them in the crate | AI23: =IF(ISBLANK(G23), "",IF(ISBLANK(AK23), TODAY()-G23, "Closed")) -> 363 | AJ23: =IF(ISBLANK(G23),"", IF(ISBLANK(AK23), "Pending", DATEDIF(G23,AK23,"d"))) -> Pending
A24: Cambridge | B24: Closed | C24: 25-015 | D24: Initial Rejection | E24: Customer | F24: Log Only | G24: 45673 | H24: =MONTH(Table1[[#This Row],[Received Date]]) -> 1 | I24: =YEAR(Table1[[#This Row],[Received Date]]) -> 2025 | J24: 58E5430653 | K24: Handle, Door Grab LH | L24: =IF(ISNUMBER(SEARCH("Axle",K24)),"Axle", IF(ISNUMBER(SEARCH("Deck",K24)),"Deck", IF(ISNUMBER(SEARCH("Cab",K24)),"Cab", IF(ISNUMBER(SEARCH("Tank",K24)),"Tank", IF(ISNUMBER(SEARCH("Grill",K24)),"Grill", IF(ISNUMBER(SEARCH("Control",K24)),"Control Box", "Other")))))) -> Other | M24: 310629 | N24: Komatsu | O24: =IF(ISNUMBER(SEARCH("mail",M24)), "Email", "") | P24: =IF(AND(200000<M24,M24<299999), 2, "") | Q24: =IF(AND(800000<M24,M24<899999), 8, "") | R24: =IF(OR(O24="Email",P24=2, Q24=8), "don't count", "count") -> count | S24: N/A | T24: N/A | U24: 44 | V24: Customer ordered 58E5430653 but we supplied them 58E5430663 and the label on the part was different too (58E5430652). | W24: Final Assembly | X24: Wrong Part | Y24: QA | AB24: Refer the print and Quality alert to make sure the part and label is correct prir to packaging | AI24: =IF(ISBLANK(G24), "",IF(ISBLANK(AK24), TODAY()-G24, "Closed")) -> 361 | AJ24: =IF(ISBLANK(G24),"", IF(ISBLANK(AK24), "Pending", DATEDIF(G24,AK24,"d"))) -> Pending
A25: Cambridge | B25: Closed | C25: 25-016 | D25: Initial Rejection | E25: Customer | F25: Log Only | G25: 45674 | H25: =MONTH(Table1[[#This Row],[Received Date]]) -> 1 | I25: =YEAR(Table1[[#This Row],[Received Date]]) -> 2025 | J25: X830027784 | K25: Cab G, Purchased | L25: =IF(ISNUMBER(SEARCH("Axle",K25)),"Axle", IF(ISNUMBER(SEARCH("Deck",K25)),"Deck", IF(ISNUMBER(SEARCH("Cab",K25)),"Cab", IF(ISNUMBER(SEARCH("Tank",K25)),"Tank", IF(ISNUMBER(SEARCH("Grill",K25)),"Grill", IF(ISNUMBER(SEARCH("Control",K25)),"Control Box", "Other")))))) -> Cab | M25: 516863 | N25: Komatsu | O25: =IF(ISNUMBER(SEARCH("mail",M25)), "Email", "") | P25: =IF(AND(200000<M25,M25<299999), 2, "") | Q25: =IF(AND(800000<M25,M25<899999), 8, "") | R25: =IF(OR(O25="Email",P25=2, Q25=8), "don't count", "count") -> count | S25: 503174 | T25: 46015 | U25: 1 | V25: Cab assy recieved at PMO with the bottom rh mm0576 weld nut welded off location on the 58E5424252 plate A.,Steering mtg. The steering column will not bolt up. | W25: Weld | X25: Off Location | Y25: QA | AB25: QA 25-012 to do a bolt check on all nuts after welding | AI25: =IF(ISBLANK(G25), "",IF(ISBLANK(AK25), TODAY()-G25, "Closed")) -> 360 | AJ25: =IF(ISBLANK(G25),"", IF(ISBLANK(AK25), "Pending", DATEDIF(G25,AK25,"d"))) -> Pending
A26: Cambridge | B26: Closed | C26: 25-017 | D26: Initial Rejection | E26: Customer | F26: Log Only | G26: 45674 | H26: =MONTH(Table1[[#This Row],[Received Date]]) -> 1 | I26: =YEAR(Table1[[#This Row],[Received Date]]) -> 2025 | J26: 58B4601802 | K26: Support, Str. | L26: =IF(ISNUMBER(SEARCH("Axle",K26)),"Axle", IF(ISNUMBER(SEARCH("Deck",K26)),"Deck", IF(ISNUMBER(SEARCH("Cab",K26)),"Cab", IF(ISNUMBER(SEARCH("Tank",K26)),"Tank", IF(ISNUMBER(SEARCH("Grill",K26)),"Grill", IF(ISNUMBER(SEARCH("Control",K26)),"Control Box", "Other")))))) -> Other | M26: 954267 | N26: Komatsu | O26: =IF(ISNUMBER(SEARCH("mail",M26)), "Email", "") | P26: =IF(AND(200000<M26,M26<299999), 2, "") | Q26: =IF(AND(800000<M26,M26<899999), 8, "") | R26: =IF(OR(O26="Email",P26=2, Q26=8), "don't count", "count") -> count | S26: 505069 | T26: 45682 | U26: 1 | V26: PPAP Part. item 33 should be welded under Item 4 both sides. Item 34&35 channe welds are low and have undercut.Welds needs to go over tacks.berries ,overlap, reentery angle lack of fusion on prep parts size on conner of the tubes | W26: Weld | X26: Undercut | AB26: QA 25-013 Debit $150 only | AI26: =IF(ISBLANK(G26), "",IF(ISBLANK(AK26), TODAY()-G26, "Closed")) -> 360 | AJ26: =IF(ISBLANK(G26),"", IF(ISBLANK(AK26), "Pending", DATEDIF(G26,AK26,"d"))) -> Pending
A27: Cambridge | B27: Closed | C27: 25-018 | D27: Initial Rejection | E27: Customer | F27: Log Only | G27: 45674 | H27: =MONTH(Table1[[#This Row],[Received Date]]) -> 1 | I27: =YEAR(Table1[[#This Row],[Received Date]]) -> 2025 | J27: 58F2200900 | K27: Axle, Housing STR | L27: =IF(ISNUMBER(SEARCH("Axle",K27)),"Axle", IF(ISNUMBER(SEARCH("Deck",K27)),"Deck", IF(ISNUMBER(SEARCH("Cab",K27)),"Cab", IF(ISNUMBER(SEARCH("Tank",K27)),"Tank", IF(ISNUMBER(SEARCH("Grill",K27)),"Grill", IF(ISNUMBER(SEARCH("Control",K27)),"Control Box", "Other")))))) -> Axle | M27: 516872 | N27: Komatsu | O27: =IF(ISNUMBER(SEARCH("mail",M27)), "Email", "") | P27: =IF(AND(200000<M27,M27<299999), 2, "") | Q27: =IF(AND(800000<M27,M27<899999), 8, "") | R27: =IF(OR(O27="Email",P27=2, Q27=8), "don't count", "count") -> count | S27: 505507 | T27: 45682 | U27: 1 | V27: During assembly at G&D rear tube str 58F2200940 was found not fitting on rear axle. Print dimension of 684 mm between 58F2200830 tapped pads measures approx 687 mm. Two different 58F2200940 tubes tried with same result. REWORK AT PMO. ORDER 1 PC OF 58F2200830 TAPPED PAD | W27: Weld | X27: Off Location | Y27: QA | AB27: Use the fixture in appropriate way and verify the measurments afterwards if Twyn shows off location. Debit $75 | AI27: =IF(ISBLANK(G27), "",IF(ISBLANK(AK27), TODAY()-G27, "Closed")) -> 360 | AJ27: =IF(ISBLANK(G27),"", IF(ISBLANK(AK27), "Pending", DATEDIF(G27,AK27,"d"))) -> Pending | AN27: Need fixture | AO27: John Megan
A28: Cambridge | B28: Closed | C28: 25-019 | D28: Initial Rejection | E28: Customer | F28: Log Only | G28: 45679 | H28: =MONTH(Table1[[#This Row],[Received Date]]) -> 1 | I28: =YEAR(Table1[[#This Row],[Received Date]]) -> 2025 | J28: 58B5421831 | K28: Control Box | L28: =IF(ISNUMBER(SEARCH("Axle",K28)),"Axle", IF(ISNUMBER(SEARCH("Deck",K28)),"Deck", IF(ISNUMBER(SEARCH("Cab",K28)),"Cab", IF(ISNUMBER(SEARCH("Tank",K28)),"Tank", IF(ISNUMBER(SEARCH("Grill",K28)),"Grill", IF(ISNUMBER(SEARCH("Control",K28)),"Control Box", "Other")))))) -> Control Box | M28: N/A | N28: Timberline/ Komatsu | O28: =IF(ISNUMBER(SEARCH("mail",M28)), "Email", "") | P28: =IF(AND(200000<M28,M28<299999), 2, "") | Q28: =IF(AND(800000<M28,M28<899999), 8, "") | R28: =IF(OR(O28="Email",P28=2, Q28=8), "don't count", "count") -> count | S28: N/A | T28: 45679 | U28: 1 | V28: Broken stud on inner left wall( May be lack of fusion) | W28: Weld | X28: Lack of Fusion | Y28: QA | AB28: Need to weld the studs with appropriate welding parameters. | AI28: =IF(ISBLANK(G28), "",IF(ISBLANK(AK28), TODAY()-G28, "Closed")) -> 355 | AJ28: =IF(ISBLANK(G28),"", IF(ISBLANK(AK28), "Pending", DATEDIF(G28,AK28,"d"))) -> Pending
A29: Stratford | B29: Closed | C29: 25-020 | D29: Initial Rejection | E29: Customer | F29: Log Only | G29: 45679 | H29: =MONTH(Table1[[#This Row],[Received Date]]) -> 1 | I29: =YEAR(Table1[[#This Row],[Received Date]]) -> 2025 | J29: 58F4600541 | K29: Upright A., L.H. STR | L29: =IF(ISNUMBER(SEARCH("Axle",K29)),"Axle", IF(ISNUMBER(SEARCH("Deck",K29)),"Deck", IF(ISNUMBER(SEARCH("Cab",K29)),"Cab", IF(ISNUMBER(SEARCH("Tank",K29)),"Tank", IF(ISNUMBER(SEARCH("Grill",K29)),"Grill", IF(ISNUMBER(SEARCH("Control",K29)),"Control Box", "Other")))))) -> Other | M29: 936421 | N29: Komatsu | O29: =IF(ISNUMBER(SEARCH("mail",M29)), "Email", "") | P29: =IF(AND(200000<M29,M29<299999), 2, "") | Q29: =IF(AND(800000<M29,M29<899999), 8, "") | R29: =IF(OR(O29="Email",P29=2, Q29=8), "don't count", "count") -> count | S29: 197979 | T29: 45658 | U29: 1 | V29: 58F4600541 found with sheet metal (58F-46-00590 & 58F-46-00580) not square and on right location. 38.0 dimension found out of specification. | W29: Weld | X29: Out of Specification | Y29: QA | AB29: 1.Engineerng needs add extra dimension to assit weld process. 2. Quality alert has been issued (25-017). | AI29: =IF(ISBLANK(G29), "",IF(ISBLANK(AK29), TODAY()-G29, "Closed")) -> 355 | AJ29: =IF(ISBLANK(G29),"", IF(ISBLANK(AK29), "Pending", DATEDIF(G29,AK29,"d"))) -> Pending
A30: Cambridge | B30: Closed | C30: 25-021 | D30: Initial Rejection | E30: Customer | F30: Log Only | G30: 45681 | H30: =MONTH(Table1[[#This Row],[Received Date]]) -> 1 | I30: =YEAR(Table1[[#This Row],[Received Date]]) -> 2025 | J30: X830027784 | K30: Cab | L30: =IF(ISNUMBER(SEARCH("Axle",K30)),"Axle", IF(ISNUMBER(SEARCH("Deck",K30)),"Deck", IF(ISNUMBER(SEARCH("Cab",K30)),"Cab", IF(ISNUMBER(SEARCH("Tank",K30)),"Tank", IF(ISNUMBER(SEARCH("Grill",K30)),"Grill", IF(ISNUMBER(SEARCH("Control",K30)),"Control Box", "Other")))))) -> Cab | M30: 516949 | N30: Komatsu | O30: =IF(ISNUMBER(SEARCH("mail",M30)), "Email", "") | P30: =IF(AND(200000<M30,M30<299999), 2, "") | Q30: =IF(AND(800000<M30,M30<899999), 8, "") | R30: =IF(OR(O30="Email",P30=2, Q30=8), "don't count", "count") -> count | S30: 503181 | T30: 45682 | U30: 1 | V30: Cab floor RH lwr sheet 58E-54-24761 has hole/weld nut off location where 58B5470490 dash bottom cover bolts to the floor. hole should measure 318mm from the egde of the lower sheet hole actually measures approx. 315mm causing cover to not properly fit. Rework in dept | W30: Weld | X30: Off Location | Y30: QA | AB30: Measurement should be taken properly during welding. | AI30: =IF(ISBLANK(G30), "",IF(ISBLANK(AK30), TODAY()-G30, "Closed")) -> 353 | AJ30: =IF(ISBLANK(G30),"", IF(ISBLANK(AK30), "Pending", DATEDIF(G30,AK30,"d"))) -> Pending
A31: Cambridge | B31: Closed | C31: 25-022 | D31: Initial Rejection | E31: Customer | F31: Log Only | G31: 45685 | H31: =MONTH(Table1[[#This Row],[Received Date]]) -> 1 | I31: =YEAR(Table1[[#This Row],[Received Date]]) -> 2025 | J31: 58B5422835 | K31: Control Box | L31: =IF(ISNUMBER(SEARCH("Axle",K31)),"Axle", IF(ISNUMBER(SEARCH("Deck",K31)),"Deck", IF(ISNUMBER(SEARCH("Cab",K31)),"Cab", IF(ISNUMBER(SEARCH("Tank",K31)),"Tank", IF(ISNUMBER(SEARCH("Grill",K31)),"Grill", IF(ISNUMBER(SEARCH("Control",K31)),"Control Box", "Other")))))) -> Control Box | M31: N/A, | N31: Liberty | O31: =IF(ISNUMBER(SEARCH("mail",M31)), "Email", "") | P31: =IF(AND(200000<M31,M31<299999), 2, "") | Q31: =IF(AND(800000<M31,M31<899999), 8, "") | R31: =IF(OR(O31="Email",P31=2, Q31=8), "don't count", "count") -> count | S31: 505079, 501223 | T31: 45685 | U31: 2 | V31: We received a defect notice from Liberty on 58B5422835 enclosure about holes not being plugged before paint, Incorrect holes plugged prior to painting, causing insufficient hole diameter | W31: Paint | X31: Missed Operation | Y31: QA | AB31: All threaded holes must be plugged in properly before paint. | AI31: =IF(ISBLANK(G31), "",IF(ISBLANK(AK31), TODAY()-G31, "Closed")) -> 349 | AJ31: =IF(ISBLANK(G31),"", IF(ISBLANK(AK31), "Pending", DATEDIF(G31,AK31,"d"))) -> Pending
